Workbook

Sheet CÁLCULO
C1: FECHAMENTO DA QUINZENA
B2: DATA: | C2: =IF(AND('BASE MANIFESTO'!B2=""), "", 'BASE MANIFESTO'!B2) -> 45992
B3: MANIFESTO: | C3: =IF(AND('BASE MANIFESTO'!A2=""), "", 'BASE MANIFESTO'!A2) -> 260574
B4: MOTORISTA: | C4: CARLOS
B5: Pontos | C5: 10 | E5: ACRÉSCIMOS | O5: Total Fixo | P5: =IFERROR(VLOOKUP(C6,'CIDADES DA ROTA SETEMBRO 2024'!B:C,2,0),0) -> 500
B6: Rota | C6: 3.1 | E6: LEME | G6: SJRPARDO | O6: Total pontos | P6: =C5*7 -> 70
B7: CIDADES ROTA: | O7: Acréscimos | P7: =IFERROR(VLOOKUP(E6,ACRÉSCIMOS!A:B,2,0),0)+IFERROR(VLOOKUP(G6,ACRÉSCIMOS!A:B,2,0),0)+IFERROR(VLOOKUP(I6,ACRÉSCIMOS!A:B,2,0),0)+IFERROR(VLOOKUP(M6,ACRÉSCIMOS!A:B,2,0),0)+IFERROR(VLOOKUP(K6,ACRÉSCIMOS!A:B,2,0),0) -> 143.82
B8: OBSERVAÇÃO: | O8: Total a receber | P8: =SUM(P5:P7) -> 713.82
B10: DATA: | C10: =IF(AND('BASE MANIFESTO'!B3=""), "", 'BASE MANIFESTO'!B3) -> 45993
B11: MANIFESTO: | C11: =IF(AND('BASE MANIFESTO'!A3=""), "", 'BASE MANIFESTO'!A3) -> 260807
B12: Pontos | C12: 9 | E12: ACRÉSCIMOS | O12: Total Fixo | P12: =IFERROR(VLOOKUP(C13,'CIDADES DA ROTA SETEMBRO 2024'!B:C,2,0),0) -> 500
B13: Rota | C13: 3.1 | E13: ESPIRITO SANTO DOS PINHAL | J13: + | O13: Total pontos | P13: =C12*7 -> 63
B14: CIDADES ROTA: | O14: Acréscimos | P14: =IFERROR(VLOOKUP(E13,ACRÉSCIMOS!A:B,2,0),0)+IFERROR(VLOOKUP(G13,ACRÉSCIMOS!A:B,2,0),0)+IFERROR(VLOOKUP(I13,ACRÉSCIMOS!A:B,2,0),0)+IFERROR(VLOOKUP(M13,ACRÉSCIMOS!A:B,2,0),0)+IFERROR(VLOOKUP(K13,ACRÉSCIMOS!A:B,2,0),0) -> 63.24
B15: OBSERVAÇÃO: | O15: Total a receber | P15: =SUM(P12:P14) -> 626.24
B17: DATA: | C17: =IF(AND('BASE MANIFESTO'!B4=""), "", 'BASE MANIFESTO'!B4) -> 45995
B18: MANIFESTO: | C18: =IF(AND('BASE MANIFESTO'!A4=""), "", 'BASE MANIFESTO'!A4) -> 261273
B19: Pontos | C19: 12 | E19: ACRÉSCIMOS | O19: Total Fixo | P19: =IFERROR(VLOOKUP(C20,'CIDADES DA ROTA SETEMBRO 2024'!B:C,2,0),0) -> 500
B20: Rota | C20: 3.1 | E20: SJRPARDO | G20: VARGEM GRANDE DO SUL | I20: ESPIRITO SANTO DOS PINHAL | J20: + | O20: Total pontos | P20: =C19*7 -> 84
B21: CIDADES ROTA: | O21: Acréscimos | P21: =IFERROR(VLOOKUP(E20,ACRÉSCIMOS!A:B,2,0),0)+IFERROR(VLOOKUP(G20,ACRÉSCIMOS!A:B,2,0),0)+IFERROR(VLOOKUP(I20,ACRÉSCIMOS!A:B,2,0),0)+IFERROR(VLOOKUP(M20,ACRÉSCIMOS!A:B,2,0),0)+IFERROR(VLOOKUP(K20,ACRÉSCIMOS!A:B,2,0),0) -> 211.14
B22: OBSERVAÇÃO: | O22: Total a receber | P22: =SUM(P19:P21) -> 795.14
B24: DATA: | C24: =IF(AND('BASE MANIFESTO'!B5=""), "", 'BASE MANIFESTO'!B5) -> 45996
B25: MANIFESTO: | C25: =IF(AND('BASE MANIFESTO'!A5=""), "", 'BASE MANIFESTO'!A5) -> 261498
B26: Pontos | C26: 11 | E26: ACRÉSCIMOS | O26: Total Fixo | P26: =IFERROR(VLOOKUP(C27,'CIDADES DA ROTA SETEMBRO 2024'!B:C,2,0),0) -> 500
B27: Rota | C27: 3.1 | E27: ESPIRITO SANTO DOS PINHAL | G27: SJRPARDO | O27: Total pontos | P27: =C26*7 -> 77
B28: CIDADES ROTA: | O28: Acréscimos | P28: =IFERROR(VLOOKUP(E27,ACRÉSCIMOS!A:B,2,0),0)+IFERROR(VLOOKUP(G27,ACRÉSCIMOS!A:B,2,0),0)+IFERROR(VLOOKUP(I27,ACRÉSCIMOS!A:B,2,0),0)+IFERROR(VLOOKUP(M27,ACRÉSCIMOS!A:B,2,0),0)+IFERROR(VLOOKUP(K27,ACRÉSCIMOS!A:B,2,0),0) -> 115.26
B29: OBSERVAÇÃO: | O29: Total a receber | P29: =SUM(P26:P28) -> 692.26
B31: DATA: | C31: =IF(AND('BASE MANIFESTO'!B6=""), "", 'BASE MANIFESTO'!B6) -> 45996
B32: MANIFESTO: | C32: =IF(AND('BASE MANIFESTO'!A6=""), "", 'BASE MANIFESTO'!A6) -> 261660
B33: Pontos | C33: 2 | E33: ACRÉSCIMOS | O33: Total Fixo | P33: =IFERROR(VLOOKUP(C34,'CIDADES DA ROTA SETEMBRO 2024'!B:C,2,0),0) -> 0
B34: Rota | E34: DEDICADO SÃO CARLOS | G34: PEDAGIO ARARAS/ SÃO CARLOS | J34: + | O34: Total pontos | P34: =C33*7 -> 14
B35: CIDADES ROTA: | O35: Acréscimos | P35: =IFERROR(VLOOKUP(E34,ACRÉSCIMOS!A:B,2,0),0)+IFERROR(VLOOKUP(G34,ACRÉSCIMOS!A:B,2,0),0)+IFERROR(VLOOKUP(I34,ACRÉSCIMOS!A:B,2,0),0)+IFERROR(VLOOKUP(M34,ACRÉSCIMOS!A:B,2,0),0)+IFERROR(VLOOKUP(K34,ACRÉSCIMOS!A:B,2,0),0) -> 451.12
B36: OBSERVAÇÃO: | O36: Total a receber | P36: =SUM(P33:P35) -> 465.12
B38: DATA: | C38: =IF(AND('BASE MANIFESTO'!B7=""), "", 'BASE MANIFESTO'!B7) -> 45999
B39: MANIFESTO: | C39: =IF(AND('BASE MANIFESTO'!A7=""), "", 'BASE MANIFESTO'!A7) -> 261756
B40: Pontos | C40: 8 | E40: ACRÉSCIMOS | O40: Total Fixo | P40: =IFERROR(VLOOKUP(C41,'CIDADES DA ROTA SETEMBRO 2024'!B:C,2,0),0) -> 500
B41: Rota | C41: 3.1 | E41: SJRPARDO | G41: LEME | O41: Total pontos | P41: =C40*7 -> 56
B42: CIDADES ROTA: | O42: Acréscimos | P42: =IFERROR(VLOOKUP(E41,ACRÉSCIMOS!A:B,2,0),0)+IFERROR(VLOOKUP(G41,ACRÉSCIMOS!A:B,2,0),0)+IFERROR(VLOOKUP(I41,ACRÉSCIMOS!A:B,2,0),0)+IFERROR(VLOOKUP(M41,ACRÉSCIMOS!A:B,2,0),0)+IFERROR(VLOOKUP(K41,ACRÉSCIMOS!A:B,2,0),0) -> 143.82
B43: OBSERVAÇÃO: | O43: Total a receber | P43: =SUM(P40:P42) -> 699.82
B45: DATA: | C45: =IF(AND('BASE MANIFESTO'!B8=""), "", 'BASE MANIFESTO'!B8) -> 46000
B46: MANIFESTO: | C46: =IF(AND('BASE MANIFESTO'!A8=""), "", 'BASE MANIFESTO'!A8) -> 261969
...

Sheet BASE MANIFESTO
A1: MANIFESTO | B1: DATA
A2: 260574 | B2: 45992
A3: 260807 | B3: 45993
A4: 261273 | B4: 45995
A5: 261498 | B5: 45996
A6: 261660 | B6: 45996
A7: 261756 | B7: 45999
A8: 261969 | B8: 46000
A9: 262190 | B9: 46001
A10: 262199 | B10: 46001
A11: 262422 | B11: 46002
A12: 262430 | B12: 46002
A13: 262640 | B13: 46003
... A24: 263846 | B24: 46008

Sheet PONTOS
A1: endereço | C1: QTDE. PONTOS | D1: =COUNTA(A2:A26) -> 11
A2: AV LEONOR MENDES DE BARROS, 626
A3: CHAMPAGNAT, CONJ 211, 863
A4: PC DR FRANCISCO LESSA, 162 - CENTRO
A5: R CORONEL ERNESTO DE OLIVEIRA, 181
A6: R DONA MARIA JOSE, 379
A7: R JOAO PESSOA, 112
A8: R TEIXEIRA RIOS, 210
A9: RUA CAROLINA MALHEIROS, 92
A10: RUA CEARA - 2 TERREO FRENTE, 222
A11: RUA FRANCISQUINHO DIAS, 583
A12: RUA ORLANDO FRACARI, 730 - RECANTO DO BOSQ

Sheet CIDADES DA ROTA SETEMBRO 2024
N1: -
B2: ROTA | C2: VALOR FIXO | D2: CIDADES
B3: 1.1 | C3: 550 | F3: S.J.DO RIO PRETO | L3: =CONCATENATE(D3,$N$1,E3,$N$1,F3,$N$1,G3,$N$1,$H$3,$N$1,I3,$N$1,J3,$N$1,K3) -> --S.J.DO RIO PRETO-----
B4: 1.4 | C4: 430 | D4: BEBEDOURO | E4: BARRETOS | F4: OLIMPIA | G4: CATANDUVA | H4: SERTAOZINHO | L4: =CONCATENATE(D4,$N$1,E4,$N$1,F4,$N$1,G4,$N$1,$H$3,$N$1,I4,$N$1,J4,$N$1,K4) -> BEBEDOURO-BARRETOS-OLIMPIA-CATANDUVA----
B5: 2.2 | C5: 390 | D5: FRANCA | E5: PASSOS | F5: SÃO SEBASTIAO DO PARAISO | G5: ALTINOPOLIS | L5: =CONCATENATE(D5,$N$1,E5,$N$1,F5,$N$1,G5,$N$1,$H$3,$N$1,I5,$N$1,J5,$N$1,K5) -> FRANCA-PASSOS-SÃO SEBASTIAO DO PARAISO-ALTINOPOLIS----
B6: 3.1 | C6: 500 | D6: PIRASSUNUNGA | E6: SÃO JOÃO DA BOA VISTA | F6: POÇOS DE CALDAS | G6: GUAXUPE | H6: MOCOCA | I6: PORTO FERREIRA | L6: =CONCATENATE(D6,$N$1,E6,$N$1,F6,$N$1,G6,$N$1,$H$3,$N$1,I6,$N$1,J6,$N$1,K6) -> PIRASSUNUNGA-SÃO JOÃO DA BOA VISTA-POÇOS DE CALDAS-GUAXUPE--PORTO FERREIRA--
B7: 3.3 | C7: 600 | D7: POÇOS DE CALDAS | E7: ALFENAS | F7: MOCOCA | L7: =CONCATENATE(D7,$N$1,E7,$N$1,F7,$N$1,G7,$N$1,$H$3,$N$1,I7,$N$1,J7,$N$1,K7) -> POÇOS DE CALDAS-ALFENAS-MOCOCA-----
B8: 4 | C8: 410 | D8: SÃO CARLOS | E8: JAU | F8: BAURU | G8: PEDERNEIRAS | L8: =CONCATENATE(D8,$N$1,E8,$N$1,F8,$N$1,G8,$N$1,$H$3,$N$1,I8,$N$1,J8,$N$1,K8) -> SÃO CARLOS-JAU-BAURU-PEDERNEIRAS----
B9: UBERLANDIA | C9: 685 | D9: ITUVERAVA | E9: ORLANDIA | F9: SÃO JOAQUIM DA BARRA | G9: UBERABA | H9: UBERLANDIA | L9: =CONCATENATE(D9,$N$1,E9,$N$1,F9,$N$1,G9,$N$1,$H$3,$N$1,I9,$N$1,J9,$N$1,K9) -> ITUVERAVA-ORLANDIA-SÃO JOAQUIM DA BARRA-UBERABA----
B10: ARARAQUARA | C10: 300 | D10: AMERICO | E10: ARARAQUARA | F10: MATAO | G10: JABOTICABAL | L10: =CONCATENATE(D10,$N$1,E10,$N$1,F10,$N$1,G10,$N$1,$H$3,$N$1,I10,$N$1,J10,$N$1,K10) -> AMERICO-ARARAQUARA-MATAO-JABOTICABAL----
B11: RIBEIRAO PRETO | C11: 270 | D11: RIBEIRÃO PRETO | L11: =CONCATENATE(D11,$N$1,E11,$N$1,F11,$N$1,G11,$N$1,$H$3,$N$1,I11,$N$1,J11,$N$1,K11) -> RIBEIRÃO PRETO-------

Sheet CIDADES DA ROTA
N1: -
B2: ROTA | C2: VALOR FIXO | D2: CIDADES
B3: 1.1 | C3: 550 | D3: BEBEDOURO | E3: OLIMPIA | F3: S.J.DO RIO PRETO | L3: =CONCATENATE(D3,$N$1,E3,$N$1,F3,$N$1,G3,$N$1,$H$3,$N$1,I3,$N$1,J3,$N$1,K3) -> BEBEDOURO-OLIMPIA-S.J.DO RIO PRETO-----
B4: 1.2 | C4: 450 | D4: OLIMPIA | E4: S.J.DO RIO PRETO | F4: CATANDUVA | G4: JABOTICABAL | L4: =CONCATENATE(D4,$N$1,E4,$N$1,F4,$N$1,G4,$N$1,$H$3,$N$1,I4,$N$1,J4,$N$1,K4) -> OLIMPIA-S.J.DO RIO PRETO-CATANDUVA-JABOTICABAL----
B5: 1.3 | C5: 330 | D5: BEBEDOURO | E5: BARRETOS | F5: OLIMPIA | L5: =CONCATENATE(D5,$N$1,E5,$N$1,F5,$N$1,G5,$N$1,$H$3,$N$1,I5,$N$1,J5,$N$1,K5) -> BEBEDOURO-BARRETOS-OLIMPIA-----
B6: 1.4 | C6: 430 | D6: BEBEDOURO | E6: BARRETOS | F6: OLIMPIA | G6: CATANDUVA | H6: JABOTICABAL | L6: =CONCATENATE(D6,$N$1,E6,$N$1,F6,$N$1,G6,$N$1,$H$3,$N$1,I6,$N$1,J6,$N$1,K6) -> BEBEDOURO-BARRETOS-OLIMPIA-CATANDUVA----
B7: 2.1 | C7: 200 | D7: FRANCA | E7: BATATAIS | L7: =CONCATENATE(D7,$N$1,E7,$N$1,F7,$N$1,G7,$N$1,$H$3,$N$1,I7,$N$1,J7,$N$1,K7) -> FRANCA-BATATAIS------
B8: 2.2 | C8: 390 | D8: FRANCA | E8: PASSOS | F8: SÃO SEBASTIAO DO PARAISO | G8: ALTINOPOLIS | L8: =CONCATENATE(D8,$N$1,E8,$N$1,F8,$N$1,G8,$N$1,$H$3,$N$1,I8,$N$1,J8,$N$1,K8) -> FRANCA-PASSOS-SÃO SEBASTIAO DO PARAISO-ALTINOPOLIS----
B9: 3.1 | C9: 460 | D9: POÇOS DE CALDAS | E9: GUAXUPE | F9: MOCOCA | L9: =CONCATENATE(D9,$N$1,E9,$N$1,F9,$N$1,G9,$N$1,$H$3,$N$1,I9,$N$1,J9,$N$1,K9) -> POÇOS DE CALDAS-GUAXUPE-MOCOCA-----
B10: 3.2 | C10: 560 | D10: PORTO FERREIRA | E10: POÇOS DE CALDAS | F10: GUAXUPÉ | G10: PASSOS | L10: =CONCATENATE(D10,$N$1,E10,$N$1,F10,$N$1,G10,$N$1,$H$3,$N$1,I10,$N$1,J10,$N$1,K10) -> PORTO FERREIRA-POÇOS DE CALDAS-GUAXUPÉ-PASSOS----
B11: 3.3 | C11: 570 | D11: POÇOS DE CALDAS | E11: ALFENAS | F11: MOCOCA | L11: =CONCATENATE(D11,$N$1,E11,$N$1,F11,$N$1,G11,$N$1,$H$3,$N$1,I11,$N$1,J11,$N$1,K11) -> POÇOS DE CALDAS-ALFENAS-MOCOCA-----
B12: 4 | C12: 410 | D12: SÃO CARLOS | E12: JAU | F12: BAURU | G12: PEDERNEIRAS | L12: =CONCATENATE(D12,$N$1,E12,$N$1,F12,$N$1,G12,$N$1,$H$3,$N$1,I12,$N$1,J12,$N$1,K12) -> SÃO CARLOS-JAU-BAURU-PEDERNEIRAS----
B13: UBERLANDIA | C13: 685 | D13: ITUVERAVA | E13: ORLANDIA | F13: SÃO JOAQUIM DA BARRA | G13: UBERABA | H13: UBERLANDIA | L13: =CONCATENATE(D13,$N$1,E13,$N$1,F13,$N$1,G13,$N$1,$H$3,$N$1,I13,$N$1,J13,$N$1,K13) -> ITUVERAVA-ORLANDIA-SÃO JOAQUIM DA BARRA-UBERABA----
B14: ARARAQUARA | C14: 300 | D14: AMERICO | E14: ARARAQUARA | F14: MATAO | G14: JABOTICABAL | H14: SERTAOZINHO | L14: =CONCATENATE(D14,$N$1,E14,$N$1,F14,$N$1,G14,$N$1,$H$3,$N$1,I14,$N$1,J14,$N$1,K14) -> AMERICO-ARARAQUARA-MATAO-JABOTICABAL----
B15: RIBEIRAO PRETO | C15: 270 | D15: RIBEIRÃO PRETO | L15: =CONCATENATE(D15,$N$1,E15,$N$1,F15,$N$1,G15,$N$1,$H$3,$N$1,I15,$N$1,J15,$N$1,K15) -> RIBEIRÃO PRETO-------

Sheet ACRÉSCIMOS
A1: CIDADES | B1: VALOR ADICIONAL R$ | C1: Distancia (km) da cabeça de rota | D1: 1.02
A2: EXTRA PIRASSUNGA | B2: =C2*D1 -> 177.48 | C2: 174
A3: EXTRA | B3: =D1*C3 -> 268.26 | C3: 263
A4: AGUDOS | B4: =C4*$D$1 -> 38.76 | C4: 38 | D4: validar esse km depois
A5: ANDRADAS | B5: =C5*$D$1 -> 52.02 | C5: 51
A6: AVARE | B6: =C6*$D$1 -> 157.08 | C6: 154
A7: BADY BASSIT | B7: =C7*$D$1 -> 19.38 | C7: 19
A8: BARIRI | B8: =C8*$D$1 -> 78.54 | C8: 77
A9: BARRETOS | B9: =C9*$D$1 -> 52.02 | C9: 51
A10: BOA ESPERANÇA | B10: =C10*$D$1 -> 102 | C10: 100
A11: BOTELHOS | B11: =C11*$D$1 -> 77.52 | C11: 76
A12: BOTUCATU | B12: =C12*$D$1 -> 111.18 | C12: 109
A13: BROTAS | B13: =C13*$D$1 -> 91.8 | C13: 90
A14: CEDRAL | B14: =C14*$D$1 -> 25.5 | C14: 25
A15: DESCALVADO | B15: =C15*$D$1 -> 52.02 | C15: 51
A16: DOIS CORREGOS | B16: =C16*$D$1 -> 59.16 | C16: 58
... A69: SERRANA | B69: =C69*$D$1 -> 25.5 | C69: 25
A70: ITAJUBA | B70: =C70*$D$1 -> 344.76 | C70: =169*2 -> 338
A71: SANTA CRUZ DAS PALMEIRAS | B71: =C71*$D$1 -> 61.2 | C71: 60
A72: VARGEM GRANDE DO SUL | B72: =C72*$D$1 -> 95.88 | C72: =47*2 -> 94
A73: SÃO PAULO | B73: =C73*$D$1 -> 426.36 | C73: =209*2 -> 418
A74: SANTA CRUZ DA ESPERANÇA | B74: =C74*$D$1 -> 221.34 | C74: 217
A75: SÃO JOAQUIM DA BARRA | B75: =C75*$D$1 -> 81.6 | C75: 80
A76: BARRA BONITA | B76: =C76*$D$1 -> 46.92 | C76: 46
A77: PIRATININGA | B77: =C77*$D$1 -> 45.9 | C77: 45
A78: MONTE ALTO | B78: =C78*$D$1 -> 42.84 | C78: 42
A79: CALDAS | B79: =C79*$D$1 -> 61.2 | C79: 60
A80: ELISIARIO | B80: =C80*$D$1 -> 40.8 | C80: 40
A81: AURIFLAMA | B81: =C81*$D$1 -> 132.6 | C81: 130
A82: JOSE BONIFACIO | B82: =C82*$D$1 -> 114.24 | C82: 112
A83: NHANDEARA | B83: =C83*$D$1 -> 73.44 | C83: 72
A84: CAJURU | B84: =C84*$D$1 -> 74.46 | C84: 73
A85: IACANGA | B85: =C85*$D$1 -> 168.3 | C85: 165
... A124: SJRP SABADO | B124: =C124*$D$1 -> 449.82 | C124: 441
A125: URGENCIA UBERLANDIA | B125: =C125*$D$1+83 -> 809.24 | C125: 712
A126: ARAÇATUBA | B126: =C126*D1 -> 816 | C126: 800
A127: PIRASSUNUNGA/ LEME | B127: =C127*D1 -> 124.44 | C127: =90+32 -> 122
A128: URUPES | B128: =C128*D1 -> 82.62 | C128: 81
A129: EXTRA CRAVINHOS/ RIBEIRÃO | B129: =C129*D1 -> 204 | C129: 200
A130: EXTRA ARARAQUARA | B130: =C130*D1 -> 142.8 | C130: 140
...

Sheet MOTORISTAS
A1: HOMERO
A2: CARLOS
A3: CRISTIANO
A4: ALTAIR
A5: DANIEL
A6: ELAINE
A7: ALEXANDRE
A8: ILSON
A9: LUIS FERNANDO
A10: ROGERIO
A11: MATHEUS
A12: EURIPEDES SILVA
A13: LEANDRO TRIVILIN
A15: FRANCISCO | B15: CLT
A16: RUBENS | B16: CLT
A17: KLEBER | B17: CLT

Sheet FECHAMENTO KM
A1: ILSON
A2: DATA | B2: MANIFESTO | C2: KM INICIAL | D2: KM FINAL | E2: KM DIA | F2: PONTOS | G2: PEDAGIO | I2: Valor KM | J2: Valor Ponto | K2: Total Pedagio
I3: 1.02 | J3: 7 | K3: =SUM(G3:G13) -> 0
I6: VALOR A PAGAR POR PONTO | K6: =J3*F15 -> 0
I7: VALOR A A PAGAR POR KM | K7: =I3*F14 -> 0
I8: VALOR A PAGAR DE PEDAGIO | K8: =K3 -> 0
I10: TOTAL A SER PAGO | K10: =SUM(K6:K8) -> 0
D14: TOTAL KM | F14: =SUM(E3:E13) -> 0
D15: TOTAL DE PONTOS | F15: =SUM(F3:F13) -> 0
D16: TOTAL DE PEDAGIOS | F16: =SUM(G4:G13) -> 0
